#VRML_SIM R2019a utf8
WorldInfo {
}
Viewpoint {
  orientation 0.31728194570804885 0.9113989087814386 0.2620766986966177 4.810609666690213
  position -3.596379445534481 3.828575735688919 1.0814969725825259
}
TexturedBackground {
}
TexturedBackgroundLight {
}
Floor {
}
Solid {
  children [
    DEF BASE Group {
      children [
        DEF CUADRADO Transform {
          translation 0 0.4125 0
          children [
            Shape {
              appearance DEF PINK PBRAppearance {
                baseColor 0.9900053406576639 0.5841000991836424 0.7283588921950103
              }
              geometry Box {
                size 0.2 0.025 0.2
              }
            }
          ]
        }
        DEF BARRA1 Transform {
          translation 0.11 0.4 0.11
          rotation 0.7071067811865475 0 -0.7071067811865475 -0.2
          children [
            Shape {
              appearance USE PINK
              geometry Cylinder {
                height 0.8
                radius 0.02
              }
            }
          ]
        }
        DEF BARRA2 Transform {
          translation 0.11 0.4 -0.11
          rotation 0.7071067811865475 0 0.7071067811865475 0.2
          children [
            Shape {
              appearance USE PINK
              geometry Cylinder {
                height 0.8
                radius 0.02
              }
            }
          ]
        }
        DEF BARRA3 Transform {
          translation -0.11 0.4 -0.11
          rotation -0.7071067811865475 0 0.7071067811865475 -0.2
          children [
            Shape {
              appearance USE PINK
              geometry Cylinder {
                height 0.8
                radius 0.02
              }
            }
          ]
        }
        DEF BARRA3 Transform {
          translation -0.11 0.4 0.11
          rotation 0.7071067811865475 0 0.7071067811865475 -0.2
          children [
            Shape {
              appearance USE PINK
              geometry Cylinder {
                height 0.8
                radius 0.02
              }
            }
          ]
        }
        DEF CUADRADO2 Transform {
          translation 0 0.8 0
          children [
            Shape {
              appearance USE PINK
              geometry Box {
                size 0.2 0.05 0.3
              }
            }
          ]
        }
      ]
    }
    DEF PIVOTE Solid {
      translation 0 0.9 0
      children [
        Shape {
          appearance DEF YELLOW PBRAppearance {
            baseColor 0.9294117647058824 0.8313725490196079 0
          }
          geometry Cylinder {
            height 0.2
            radius 0.02
          }
        }
        DEF CYL2 Transform {
          translation 0 0.13999999999999999 0.049999999999999996
          rotation 1 0 0 1.57
          children [
            DEF CYL_2 Shape {
              appearance USE YELLOW
              geometry Cylinder {
                height 0.2
                radius 0.05
              }
            }
            DEF COLITA HingeJoint {
              jointParameters HingeJointParameters {
                axis 0 0 1
                anchor 0 -0.1 -0.02
                minStop -0.2
                maxStop 0.2
              }
              endPoint Solid {
                translation 0 -0.25 0
                children [
                  Shape {
                    appearance USE YELLOW
                    geometry Cylinder {
                      height 0.3
                      radius 0.02
                    }
                  }
                  Transform {
                    translation 0 -0.2 0
                    children [
                      Shape {
                        appearance USE YELLOW
                        geometry Box {
                          size 0.04 0.1 0.1
                        }
                      }
                    ]
                  }
                ]
                name "solid(1)"
                physics Physics {
                }
              }
            }
            DEF BOLITA Transform {
              translation 0 0.1 0
              children [
                Shape {
                  appearance USE YELLOW
                  geometry Sphere {
                    radius 0.02
                  }
                }
                HingeJoint {
                  jointParameters HingeJointParameters {
                    axis 0 1 0
                    anchor 0 0.03 0
                  }
                  endPoint Solid {
                    children [
                      DEF LIN1 Group {
                        children [
                          DEF CAJITA Transform {
                            translation 0 0.03 0
                            children [
                              DEF PARADO Shape {
                                appearance USE YELLOW
                                geometry Box {
                                  size 0.01 0.01 0.2
                                }
                              }
                              DEF FINAL1 Transform {
                                translation 0 0 0.1
                                children [
                                  DEF FINAL Shape {
                                    appearance USE YELLOW
                                    geometry Box {
                                      size 0.04 0.005 0.1
                                    }
                                  }
                                ]
                              }
                              DEF FINAL1 Transform {
                                translation 0 0 -0.1
                                children [
                                  DEF FINAL Shape {
                                    appearance USE YELLOW
                                    geometry Box {
                                      size 0.04 0.005 0.1
                                    }
                                  }
                                ]
                              }
                            ]
                          }
                          DEF CAJITA2 Transform {
                            translation 0 0.03 0
                            rotation 0 1 0 1.57
                            children [
                              DEF PARADO Shape {
                                appearance USE YELLOW
                                geometry Box {
                                  size 0.01 0.01 0.2
                                }
                              }
                              DEF FINAL1 Transform {
                                translation 0 0 0.1
                                children [
                                  DEF FINAL Shape {
                                    appearance USE YELLOW
                                    geometry Box {
                                      size 0.04 0.005 0.1
                                    }
                                  }
                                ]
                              }
                              DEF FINAL1 Transform {
                                translation 0 0 -0.1
                                children [
                                  DEF FINAL Shape {
                                    appearance USE YELLOW
                                    geometry Box {
                                      size 0.04 0.005 0.1
                                    }
                                  }
                                ]
                              }
                            ]
                          }
                        ]
                      }
                      Transform {
                        rotation 0 1 0 0.7854
                        children [
                          DEF LIN1 Group {
                            children [
                              DEF CAJITA Transform {
                                translation 0 0.03 0
                                children [
                                  DEF PARADO Shape {
                                    appearance USE YELLOW
                                    geometry Box {
                                      size 0.01 0.01 0.2
                                    }
                                  }
                                  DEF FINAL1 Transform {
                                    translation 0 0 0.1
                                    children [
                                      DEF FINAL Shape {
                                        appearance USE YELLOW
                                        geometry Box {
                                          size 0.04 0.005 0.1
                                        }
                                      }
                                    ]
                                  }
                                  DEF FINAL1 Transform {
                                    translation 0 0 -0.1
                                    children [
                                      DEF FINAL Shape {
                                        appearance USE YELLOW
                                        geometry Box {
                                          size 0.04 0.005 0.1
                                        }
                                      }
                                    ]
                                  }
                                ]
                              }
                              DEF CAJITA2 Transform {
                                translation 0 0.03 0
                                rotation 0 1 0 1.57
                                children [
                                  DEF PARADO Shape {
                                    appearance USE YELLOW
                                    geometry Box {
                                      size 0.01 0.01 0.2
                                    }
                                  }
                                  DEF FINAL1 Transform {
                                    translation 0 0 0.1
                                    children [
                                      DEF FINAL Shape {
                                        appearance USE YELLOW
                                        geometry Box {
                                          size 0.04 0.005 0.1
                                        }
                                      }
                                    ]
                                  }
                                  DEF FINAL1 Transform {
                                    translation 0 0 -0.1
                                    children [
                                      DEF FINAL Shape {
                                        appearance USE YELLOW
                                        geometry Box {
                                          size 0.04 0.005 0.1
                                        }
                                      }
                                    ]
                                  }
                                ]
                              }
                            ]
                          }
                        ]
                      }
                    ]
                    physics Physics {
                    }
                  }
                }
              ]
            }
          ]
        }
      ]
    }
  ]
}
